<?xml version="1.0"?>
<robot xmlns:xacro="http://ros.org/wiki/xacro">
  <xacro:macro name="abb_irb4600_20_250" params="prefix">
    <xacro:include filename="$(find abb_resources)/urdf/common_materials.xacro"/>

    <!--Materials-->
    <material name="white">
      <color rgba="1 1 1 1"/>
    </material>
    <material name="black">
      <color rgba="0.1 0.1 0.1 1"/>
    </material>
    <material name="silver" >
      <color rgba="0.7725490196078432 0.788235294117647 0.7803921568627451 1.0" />
    </material>

    <!-- link list -->

    <link name="base_link">
      <visual>
        <geometry>
          <box size="3.25 2.28 -0.01"/>
          <!--<box size="3.25 2.28 -0.01"/>-->
        </geometry>
        <material name="silver"/>
      </visual>
    </link>
    <link name="robot_base_cylinder_link">
      <visual>
        <geometry>
          <cylinder length="0.533" radius="0.292"/>
        </geometry>
        <material name="black"/>
      </visual>
    </link>
    <!--link name="pos_link"-->
      <!--visual-->
        <!--geometry-->
          <!--box size="1 1 2"/-->
        <!--/geometry-->
        <!--xacro:material_abb_graphite_white/-->
      <!--/visual-->
    <!--/link-->

    <link name="${prefix}robot_base_link">
      <collision name="collision">
        <geometry>
          <mesh filename="package://abb_irb4600_support/meshes/irb4600_20_250/collision/base_link.stl"/>
        </geometry>
        <xacro:material_abb_yellow />
      </collision>
      <visual name="visual">
        <geometry>
          <mesh filename="package://abb_irb4600_support/meshes/irb4600_20_250/visual/base_link.stl"/>
        </geometry>
        <xacro:material_abb_graphite_white/>
      </visual>
    </link>
    <link name="${prefix}link_1">
      <collision name="collision">
        <geometry>
          <mesh filename="package://abb_irb4600_support/meshes/irb4600_20_250/collision/link_1.stl"/>
        </geometry>
        <xacro:material_abb_yellow />
      </collision>
      <visual name="visual">
        <geometry>
          <mesh filename="package://abb_irb4600_support/meshes/irb4600_20_250/visual/link_1.stl"/>
        </geometry>
        <xacro:material_abb_graphite_white/>
      </visual>
    </link>
    <link name="${prefix}link_2">
      <collision name="collision">
        <geometry>
          <mesh filename="package://abb_irb4600_support/meshes/irb4600_20_250/collision/link_2.stl"/>
        </geometry>
        <xacro:material_abb_yellow />
      </collision>
      <visual name="visual">
        <geometry>
          <mesh filename="package://abb_irb4600_support/meshes/irb4600_20_250/visual/link_2.stl"/>
        </geometry>
        <xacro:material_abb_graphite_white/>
      </visual>
    </link>
    <link name="${prefix}link_3">
      <collision name="collision">
        <geometry>
          <mesh filename="package://abb_irb4600_support/meshes/irb4600_20_250/collision/link_3.stl"/>
        </geometry>
        <xacro:material_abb_yellow />
      </collision>
      <visual name="visual">
        <geometry>
          <mesh filename="package://abb_irb4600_support/meshes/irb4600_20_250/visual/link_3.stl"/>
        </geometry>
        <xacro:material_abb_graphite_white/>
      </visual>
    </link>
    <link name="${prefix}link_4">
      <collision name="collision">
        <geometry>
          <mesh filename="package://abb_irb4600_support/meshes/irb4600_20_250/collision/link_4.stl"/>
        </geometry>
        <xacro:material_abb_yellow />
      </collision>
      <visual name="visual">
        <geometry>
          <mesh filename="package://abb_irb4600_support/meshes/irb4600_20_250/visual/link_4.stl"/>
        </geometry>
        <xacro:material_abb_graphite_white/>
      </visual>
    </link>
    <link name="${prefix}link_5">
      <collision name="collision">
        <geometry>
          <mesh filename="package://abb_irb4600_support/meshes/irb4600_20_250/collision/link_5.stl"/>
        </geometry>
        <xacro:material_abb_yellow />
      </collision>
      <visual name="visual">
        <geometry>
          <mesh filename="package://abb_irb4600_support/meshes/irb4600_20_250/visual/link_5.stl"/>
        </geometry>
        <xacro:material_abb_graphite_white/>
      </visual>
    </link>
    <link name="${prefix}link_6">
      <collision name="collision">
        <geometry>
          <mesh filename="package://abb_irb4600_support/meshes/irb4600_20_250/collision/link_6.stl"/>
        </geometry>
        <xacro:material_abb_yellow />
      </collision>
      <visual name="visual">
        <geometry>
          <mesh filename="package://abb_irb4600_support/meshes/irb4600_20_250/visual/link_6.stl"/>
        </geometry>
        <xacro:material_abb_graphite_white/>
      </visual>
    </link>
    <link name="${prefix}end_effector">
      <origin xyz="0 0 0" rpy="0 0 0"/>
      <visual name="visual">
        <geometry>
          <mesh filename="package://abb_irb4600_support/meshes/irb4600_20_250/visual/EndEffectorv2.stl"/>
        </geometry>
        <xacro:material_abb_graphite_white/>
      </visual>
    </link>
    <link name="${prefix}pos_link">
      <origin xyz="0 0 0" rpy="0 0 0"/>
      <visual name="visual">
        <geometry>
          <mesh filename="package://abb_irb4600_support/meshes/irb4600_20_250/visual/pos_link.stl"/>
        </geometry>
        <xacro:material_abb_graphite_white/>
      </visual>
    </link>

    <!-- end of link list -->

    <!-- joint list -->
    <joint type="fixed" name="${prefix}joint_base_cylinder">
      <origin xyz="-0.5 0 0.266" rpy="0 0 0"/>
      <axis xyz="0 0 1"/>
      <parent link="${prefix}base_link"/>
      <child link="${prefix}robot_base_cylinder_link"/>
    </joint>
    <joint type="fixed" name="${prefix}joint_0">
      <origin xyz="-0.5 0 0.6" rpy="0 0 0"/>
      <axis xyz="0 0 1"/>
      <parent link="${prefix}base_link"/>
      <child link="${prefix}robot_base_link"/>
    </joint>
    <joint type="revolute" name="${prefix}joint_1">
      <origin xyz="0 0 0.445" rpy="0 0 0"/>
      <axis xyz="0 0 1"/>
      <parent link="${prefix}robot_base_link"/>
      <child link="${prefix}link_1"/>
      <limit effort="0" lower="${radians(-180)}" upper="${radians(180)}" velocity="${radians(175)}"/>
    </joint>
    <joint type="revolute" name="${prefix}joint_2">
      <origin xyz="0.15 0 0" rpy="0 0 0"/>
      <axis xyz="0 1 0"/>
      <parent link="${prefix}link_1"/>
      <child link="${prefix}link_2"/>
      <limit effort="0" lower="-2.705"  upper="1.658"  velocity="3.054"/>
    </joint>
    <joint type="revolute" name="${prefix}joint_3">
      <origin xyz="0 0 0.7" rpy="0 0.23 0"/>
      <axis xyz="0 1 0"/>
      <parent link="${prefix}link_2"/>
      <child link="${prefix}link_3"/>
      <limit effort="0" lower="${radians(-180)}" upper="${radians(75)}" velocity="${radians(175)}"/>
    </joint>
    <joint type="revolute" name="${prefix}joint_4">
      <origin xyz="0 0 0.115" rpy="0 0 0"/>
      <axis xyz="1 0 0"/>
      <parent link="${prefix}link_3"/>
      <child link="${prefix}link_4"/>
      <limit effort="0" lower="${radians(-400)}" upper="${radians(400)}" velocity="${radians(360)}"/>
    </joint>
    <joint type="revolute" name="${prefix}joint_5">
      <origin xyz="0.795 0 0" rpy="0 1.35 0"/>
      <axis xyz="0 1 0"/>
      <parent link="${prefix}link_4"/>
      <child link="${prefix}link_5"/>
      <limit effort="0" lower="${radians(-125)}" upper="${radians(120)}" velocity="${radians(360)}"/>
    </joint>
    <joint type="revolute" name="${prefix}joint_6">
      <origin xyz="0.085 0 0" rpy="-0.49 0 0"/>
      <axis xyz="1 0 0"/>
      <parent link="${prefix}link_5"/>
      <child link="${prefix}link_6"/>
      <limit effort="0" lower="${radians(-400)}" upper="${radians(400)}" velocity="${radians(500)}"/>
    </joint>
    <joint type="fixed"  name="${prefix}flange-End_Effector">
      <origin xyz="0 0 0" rpy="0 ${radians(90)} 0"/>
      <parent link="${prefix}flange"/>
      <child link="${prefix}end_effector"/>
    </joint>
    
    <joint name="${prefix}pos_base_joint" type="fixed">
      <origin xyz="0.5 0 0" rpy="0 0 0"/>
      <parent link="base_link"/>
      <child link="${prefix}pos_link"/>
    </joint>
    <!-- end of joint list -->

    <!-- ROS-Industrial 'base' frame- base_link to ABB World Coordinates transform -->
    <link name="${prefix}base" />
    <joint name="${prefix}robot_base_link-base" type="fixed">
      <origin xyz="0 0 0" rpy="0 0 0"/>
      <parent link="${prefix}robot_base_link"/>
      <child link="${prefix}base"/>
    </joint>

    <!-- ROS-Industrial 'Positioner' frame- base_link to ABB World Coordinates transform -->
    <!--link name="${prefix}base2" /-->
    <!--joint name="${prefix}pos_link-base" type="fixed"-->
      <!--origin xyz="10 0.5 0" rpy="0 0 0"/-->
      <!--parent link="${prefix}base_link"/-->
      <!--child link="${prefix}pos_link"/-->
    <!--/joint-->


    <!-- ROS-Industrial 'flange' frame- attachment point for EEF models -->
    <link name="${prefix}flange"/>
    <joint type="fixed" name="${prefix}joint_6-flange">
      <origin xyz="0 0 0" rpy="0 0 0"/>
      <parent link="${prefix}link_6"/>
      <child link="${prefix}flange"/>
    </joint>

    <!-- ROS-Industrial 'tool0' frame- all-zeros tool frame -->
    <link name="${prefix}tool0" />
    <joint name="${prefix}link_6-tool0" type="fixed">
      <origin xyz="0 0 0" rpy="0 ${radians(90)} 0" />
      <parent link="${prefix}flange" />
      <child link="${prefix}tool0" />
    </joint>


  </xacro:macro>
</robot>
